Workbook
Name Dilimleyici_ErrorType: #N/A
Name Slicer_Department: #N/A
Name Slicer_MachineCode: #N/A
Name Slicer_Months__ProductionDate: #N/A
Name Slicer_ProductCode: #N/A
Name Slicer_ProductionLine: #N/A
Name Slicer_QualityInspector: #N/A
Name Slicer_Shift: #N/A

Sheet Dashboard

Sheet Error Analysis

Sheet Data Set
A1: ProductionDate | B1: Department | C1: Shift | D1: MachineCode | E1: ProductionLine | F1: ProductCode | G1: ErrorType | H1: ErrorDescription | I1: ErrorSeverity (1–5) | J1: ErrorProbability (%) | K1: ErrorFrequency (units/day) | L1: ErrorCost (TL/unit) | M1: CorrectionTime (minutes) | N1: QualityInspector | O1: DefectiveUnits | P1: TotalProduction | Q1: shownote | R1: Notes | S1: ErrorRate (%) | T1: QualityScore (0–100) | U1: KPI – AverageCorrectionCost (TL) | V1: risk score | W1: Total Cost | X1: quality classes | Y1: distribution | Z1: bins | AA1: countifs | AB1: normdist | AC1: uniform | AD1: mean | AE1: stdev
A2: 45331 | B2: Paketleme | C2: 2 | D2: MK-010 | E2: Hat D | F2: UR-1014 | G2: Ölçü Hatası | H2: Renk farkı | I2: 2 | J2: 11.35 | K2: 5 | L2: 465.16 | M2: 83 | N2: Ece | O2: 30 | P2: 306 | Q2: =IF(D2=Pivot!$AS$4,R1, "") | R2: Kontrol tekrarlandı | S2: 9.8 | T2: 78.4 | U2: 643.47 | V2: =K2*I2*J2 -> 113.5 | W2: =U2+L2 -> 1108.63 | X2: =_xlfn.IFS(J2<6,"High Quality",J2<=15,"Mid Quality",J2>15,"Low Quality") -> Mid Quality | Y2: =_xlfn.IFS(J2<=0,"0",J2<=2,"2",J2<=4,"4",J2<=6,"6",J2<=8,"8",J2<=10,"10",J2<=12,"12",J2<=14,"14",J2<=16,"16",J2<=16,"16",J2<=18,"18",J2<=20,"20") -> 12 | Z2: 0 | AA2: =COUNTIF(J:J,"<=0") -> 0 | AB2: =_xlfn.NORM.DIST(Table2[[#This Row],[bins]],$AD$2,$AE$2,FALSE) -> 0.012441599 | AC2: 0.05 | AD2: =AVERAGE(J:J) -> 10.33658 | AE2: =_xlfn.STDEV.P(J:J) -> 5.5065488
A3: 45330 | B3: CNC | C3: 1 | D3: MK-014 | E3: Hat C | F3: UR-1002 | G3: Yüzey Çizik | H3: Kaynak atlaması | I3: 5 | J3: 6.13 | K3: 4 | L3: 305.81 | M3: 38 | N3: Ece | O3: 41 | P3: 785 | Q3: =IF(D3=Pivot!$AS$4,R2, "") | R3: Kritik hata | S3: 5.22 | T3: 84.56 | U3: 193.68 | V3: =K3*I3*J3 -> 122.6 | W3: =U3+L3 -> 499.49 | X3: =_xlfn.IFS(J3<6,"High Quality",J3<=15,"Mid Quality",J3>15,"Low Quality") -> Mid Quality | Y3: =_xlfn.IFS(J3<=0,"0",J3<=2,"2",J3<=4,"4",J3<=6,"6",J3<=8,"8",J3<=10,"10",J3<=12,"12",J3<=14,"14",J3<=16,"16",J3<=16,"16",J3<=18,"18",J3<=20,"20") -> 8 | Z3: 2 | AA3: =COUNTIFS(J:J,">0",J:J,"<=2") -> 55 | AB3: =_xlfn.NORM.DIST(Table2[[#This Row],[bins]],$AD$2,$AE$2,FALSE) -> 0.023031728 | AC3: 0.05
A4: 45301 | B4: Kaynak | C4: 2 | D4: MK-011 | E4: Hat E | F4: UR-1004 | G4: Renk Uyumsuzluğu | H4: Tolerans dışı ölçüm | I4: 3 | J4: 14.35 | K4: 5 | L4: 213.68 | M4: 74 | N4: Mehmet | O4: 38 | P4: 795 | Q4: =IF(D4=Pivot!$AS$4,R3, "") | R4: Makine ayarı değiştirildi | S4: 4.78 | T4: 87.44 | U4: 263.54 | V4: =K4*I4*J4 -> 215.25 | W4: =U4+L4 -> 477.22 | X4: =_xlfn.IFS(J4<6,"High Quality",J4<=15,"Mid Quality",J4>15,"Low Quality") -> Mid Quality | Y4: =_xlfn.IFS(J4<=0,"0",J4<=2,"2",J4<=4,"4",J4<=6,"6",J4<=8,"8",J4<=10,"10",J4<=12,"12",J4<=14,"14",J4<=16,"16",J4<=16,"16",J4<=18,"18",J4<=20,"20") -> 16 | Z4: 4 | AA4: =COUNTIFS(J:J,">2",J:J,"<=4") -> 112 | AB4: =_xlfn.NORM.DIST(Table2[[#This Row],[bins]],$AD$2,$AE$2,FALSE) -> 0.037366808 | AC4: 0.05
A5: 45551 | B5: CNC | C5: 2 | D5: MK-018 | E5: Hat D | F5: UR-1000 | G5: Yüzey Çizik | H5: Renk farkı | I5: 5 | J5: 13.52 | K5: 8 | L5: 390.44 | M5: 21 | N5: Ahmet | O5: 29 | P5: 364 | Q5: =IF(D5=Pivot!$AS$4,R4, "") | R5: Eğitim önerildi | S5: 7.97 | T5: 79.06 | U5: 136.65 | V5: =K5*I5*J5 -> 540.8 | W5: =U5+L5 -> 527.09 | X5: =_xlfn.IFS(J5<6,"High Quality",J5<=15,"Mid Quality",J5>15,"Low Quality") -> Mid Quality | Y5: =_xlfn.IFS(J5<=0,"0",J5<=2,"2",J5<=4,"4",J5<=6,"6",J5<=8,"8",J5<=10,"10",J5<=12,"12",J5<=14,"14",J5<=16,"16",J5<=16,"16",J5<=18,"18",J5<=20,"20") -> 14 | Z5: 6 | AA5: =COUNTIFS(J:J,">4",J:J,"<=6") -> 106 | AB5: =_xlfn.NORM.DIST(Table2[[#This Row],[bins]],$AD$2,$AE$2,FALSE) -> 0.053131811 | AC5: 0.05
A6: 45307 | B6: CNC | C6: 3 | D6: MK-012 | E6: Hat C | F6: UR-1002 | G6: Yüzey Çizik | H6: Yüzey deformasyonu | I6: 5 | J6: 19.79 | K6: 4 | L6: 165.81 | M6: 24 | N6: Zeynep | O6: 43 | P6: 857 | Q6: =IF(D6=Pivot!$AS$4,R5, "") | R6: Kontrol tekrarlandı | S6: 5.02 | T6: 84.96 | U6: 66.32 | V6: =K6*I6*J6 -> 395.8 | W6: =U6+L6 -> 232.13 | X6: =_xlfn.IFS(J6<6,"High Quality",J6<=15,"Mid Quality",J6>15,"Low Quality") -> Low Quality | Y6: =_xlfn.IFS(J6<=0,"0",J6<=2,"2",J6<=4,"4",J6<=6,"6",J6<=8,"8",J6<=10,"10",J6<=12,"12",J6<=14,"14",J6<=16,"16",J6<=16,"16",J6<=18,"18",J6<=20,"20") -> 20 | Z6: 8 | AA6: =COUNTIFS(J:J,">6",J:J,"<=8") -> 110 | AB6: =_xlfn.NORM.DIST(Table2[[#This Row],[bins]],$AD$2,$AE$2,FALSE) -> 0.066211341 | AC6: 0.05
A7: 45589 | B7: Boya | C7: 2 | D7: MK-012 | E7: Hat A | F7: UR-1014 | G7: Kaynak Hatası | H7: Renk farkı | I7: 1 | J7: 6.04 | K7: 9 | L7: 362.08 | M7: 77 | N7: Mehmet | O7: 39 | P7: 135 | Q7: =IF(D7=Pivot!$AS$4,R6, "") | R7: Makine ayarı değiştirildi | S7: 28.89 | T7: 41.22 | U7: 464.67 | V7: =K7*I7*J7 -> 54.36 | W7: =U7+L7 -> 826.75 | X7: =_xlfn.IFS(J7<6,"High Quality",J7<=15,"Mid Quality",J7>15,"Low Quality") -> Mid Quality | Y7: =_xlfn.IFS(J7<=0,"0",J7<=2,"2",J7<=4,"4",J7<=6,"6",J7<=8,"8",J7<=10,"10",J7<=12,"12",J7<=14,"14",J7<=16,"16",J7<=16,"16",J7<=18,"18",J7<=20,"20") -> 8 | Z7: 10 | AA7: =COUNTIFS(J:J,">8",J:J,"<=10") -> 106 | AB7: =_xlfn.NORM.DIST(Table2[[#This Row],[bins]],$AD$2,$AE$2,FALSE) -> 0.072313485 | AC7: 0.05
A8: 45588 | B8: Kaynak | C8: 3 | D8: MK-013 | E8: Hat D | F8: UR-1007 | G8: Ölçü Hatası | H8: Renk farkı | I8: 1 | J8: 13.77 | K8: 7 | L8: 67.87 | M8: 63 | N8: Ayşe | O8: 4 | P8: 472 | Q8: =IF(D8=Pivot!$AS$4,R7, "") | R8: Eğitim önerildi | S8: 0.85 | T8: 97.3 | U8: 71.26 | V8: =K8*I8*J8 -> 96.39 | W8: =U8+L8 -> 139.13 | X8: =_xlfn.IFS(J8<6,"High Quality",J8<=15,"Mid Quality",J8>15,"Low Quality") -> Mid Quality | Y8: =_xlfn.IFS(J8<=0,"0",J8<=2,"2",J8<=4,"4",J8<=6,"6",J8<=8,"8",J8<=10,"10",J8<=12,"12",J8<=14,"14",J8<=16,"16",J8<=16,"16",J8<=18,"18",J8<=20,"20") -> 14 | Z8: 12 | AA8: =COUNTIFS(J:J,">10",J:J,"<=12") -> 118 | AB8: =_xlfn.NORM.DIST(Table2[[#This Row],[bins]],$AD$2,$AE$2,FALSE) -> 0.06921741 | AC8: 0.05 | AG8: UNİFORM
A9: 45499 | B9: Kaynak | C9: 2 | D9: MK-013 | E9: Hat C | F9: UR-1003 | G9: Yüzey Çizik | H9: Tolerans dışı ölçüm | I9: 1 | J9: 1.99 | K9: 7 | L9: 427.73 | M9: 73 | N9: Zeynep | O9: 5 | P9: 587 | Q9: =IF(D9=Pivot!$AS$4,R8, "") | R9: Rutin kontrol | S9: 0.85 | T9: 97.3 | U9: 520.4 | V9: =K9*I9*J9 -> 13.93 | W9: =U9+L9 -> 948.13 | X9: =_xlfn.IFS(J9<6,"High Quality",J9<=15,"Mid Quality",J9>15,"Low Quality") -> High Quality | Y9: =_xlfn.IFS(J9<=0,"0",J9<=2,"2",J9<=4,"4",J9<=6,"6",J9<=8,"8",J9<=10,"10",J9<=12,"12",J9<=14,"14",J9<=16,"16",J9<=16,"16",J9<=18,"18",J9<=20,"20") -> 2 | Z9: 14 | AA9: =COUNTIFS(J:J,">12",J:J,"<=14") -> 90 | AB9: =_xlfn.NORM.DIST(Table2[[#This Row],[bins]],$AD$2,$AE$2,FALSE) -> 0.058065816 | AC9: 0.05 | AG9: 1/MAX-MİN
A10: 45400 | B10: Kaynak | C10: 2 | D10: MK-019 | E10: Hat A | F10: UR-1001 | G10: Eksik Parça | H10: Eksik vida | I10: 5 | J10: 3.16 | K10: 8 | L10: 251.68 | M10: 37 | N10: Ayşe | O10: 4 | P10: 358 | Q10: =IF(D10=Pivot!$AS$4,R9, "") | R10: Makine ayarı değiştirildi | S10: 1.12 | T10: 92.76 | U10: 155.2 | V10: =K10*I10*J10 -> 126.4 | W10: =U10+L10 -> 406.88 | X10: =_xlfn.IFS(J10<6,"High Quality",J10<=15,"Mid Quality",J10>15,"Low Quality") -> High Quality | Y10: =_xlfn.IFS(J10<=0,"0",J10<=2,"2",J10<=4,"4",J10<=6,"6",J10<=8,"8",J10<=10,"10",J10<=12,"12",J10<=14,"14",J10<=16,"16",J10<=16,"16",J10<=18,"18",J10<=20,"20") -> 4 | Z10: 16 | AA10: =COUNTIFS(J:J,">14",J:J,"<=16") -> 89 | AB10: =_xlfn.NORM.DIST(Table2[[#This Row],[bins]],$AD$2,$AE$2,FALSE) -> 0.042690857 | AC10: 0.05 | AG10: 1/20-0
A11: 45310 | B11: CNC | C11: 2 | D11: MK-019 | E11: Hat E | F11: UR-1009 | G11: Ölçü Hatası | H11: Eksik vida | I11: 2 | J11: 1.07 | K11: 6 | L11: 336.51 | M11: 82 | N11: Burak | O11: 36 | P11: 630 | Q11: =IF(D11=Pivot!$AS$4,R10, "") | R11: Rutin kontrol | S11: 5.71 | T11: 86.58 | U11: 459.9 | V11: =K11*I11*J11 -> 12.84 | W11: =U11+L11 -> 796.41 | X11: =_xlfn.IFS(J11<6,"High Quality",J11<=15,"Mid Quality",J11>15,"Low Quality") -> High Quality | Y11: =_xlfn.IFS(J11<=0,"0",J11<=2,"2",J11<=4,"4",J11<=6,"6",J11<=8,"8",J11<=10,"10",J11<=12,"12",J11<=14,"14",J11<=16,"16",J11<=16,"16",J11<=18,"18",J11<=20,"20") -> 2 | Z11: 18 | AA11: =COUNTIFS(J:J,">16",J:J,"<=18") -> 105 | AB11: =_xlfn.NORM.DIST(Table2[[#This Row],[bins]],$AD$2,$AE$2,FALSE) -> 0.027507958 | AC11: 0.05
A12: 45574 | B12: Paketleme | C12: 3 | D12: MK-014 | E12: Hat E | F12: UR-1003 | G12: Renk Uyumsuzluğu | H12: Eksik vida | I12: 3 | J12: 19.99 | K12: 8 | L12: 149.56 | M12: 21 | N12: Ayşe | O12: 45 | P12: 122 | Q12: =IF(D12=Pivot!$AS$4,R11, "") | R12: Kritik hata | S12: 36.89 | T12: 23.22 | U12: 52.35 | V12: =K12*I12*J12 -> 479.76 | W12: =U12+L12 -> 201.91 | X12: =_xlfn.IFS(J12<6,"High Quality",J12<=15,"Mid Quality",J12>15,"Low Quality") -> Low Quality | Y12: =_xlfn.IFS(J12<=0,"0",J12<=2,"2",J12<=4,"4",J12<=6,"6",J12<=8,"8",J12<=10,"10",J12<=12,"12",J12<=14,"14",J12<=16,"16",J12<=16,"16",J12<=18,"18",J12<=20,"20") -> 20 | Z12: 20 | AA12: =COUNTIFS(J:J,">18",J:J,"<=20") -> 109 | AB12: =_xlfn.NORM.DIST(Table2[[#This Row],[bins]],$AD$2,$AE$2,FALSE) -> 0.015534274 | AC12: 0.05
A13: 45425 | B13: Kaynak | C13: 3 | D13: MK-004 | E13: Hat E | F13: UR-1002 | G13: Kaynak Hatası | H13: Renk farkı | I13: 3 | J13: 16.24 | K13: 3 | L13: 354.68 | M13: 61 | N13: Zeynep | O13: 16 | P13: 203 | Q13: =IF(D13=Pivot!$AS$4,R12, "") | R13: Rutin kontrol | S13: 7.88 | T13: 81.24 | U13: 360.59 | V13: =K13*I13*J13 -> 146.16 | W13: =U13+L13 -> 715.27 | X13: =_xlfn.IFS(J13<6,"High Quality",J13<=15,"Mid Quality",J13>15,"Low Quality") -> Low Quality | Y13: =_xlfn.IFS(J13<=0,"0",J13<=2,"2",J13<=4,"4",J13<=6,"6",J13<=8,"8",J13<=10,"10",J13<=12,"12",J13<=14,"14",J13<=16,"16",J13<=16,"16",J13<=18,"18",J13<=20,"20") -> 18
A14: 45570 | B14: Pres | C14: 1 | D14: MK-013 | E14: Hat E | F14: UR-1001 | G14: Renk Uyumsuzluğu | H14: Tolerans dışı ölçüm | I14: 2 | J14: 15.95 | K14: 1 | L14: 397.51 | M14: 87 | N14: Burak | O14: 25 | P14: 340 | Q14: =IF(D14=Pivot!$AS$4,R13, "") | R14: Makine ayarı değiştirildi | S14: 7.35 | T14: 83.3 | U14: 576.39 | V14: =K14*I14*J14 -> 31.9 | W14: =U14+L14 -> 973.9 | X14: =_xlfn.IFS(J14<6,"High Quality",J14<=15,"Mid Quality",J14>15,"Low Quality") -> Low Quality | Y14: =_xlfn.IFS(J14<=0,"0",J14<=2,"2",J14<=4,"4",J14<=6,"6",J14<=8,"8",J14<=10,"10",J14<=12,"12",J14<=14,"14",J14<=16,"16",J14<=16,"16",J14<=18,"18",J14<=20,"20") -> 16
A15: 45568 | B15: CNC | C15: 3 | D15: MK-008 | E15: Hat B | F15: UR-1016 | G15: Renk Uyumsuzluğu | H15: Kaynak atlaması | I15: 2 | J15: 10.68 | K15: 6 | L15: 262.95 | M15: 5 | N15: Zeynep | O15: 14 | P15: 972 | Q15: =IF(D15=Pivot!$AS$4,R14, "") | R15: Rutin kontrol | S15: 1.44 | T15: 95.12 | U15: 21.91 | V15: =K15*I15*J15 -> 128.16 | W15: =U15+L15 -> 284.86 | X15: =_xlfn.IFS(J15<6,"High Quality",J15<=15,"Mid Quality",J15>15,"Low Quality") -> Mid Quality | Y15: =_xlfn.IFS(J15<=0,"0",J15<=2,"2",J15<=4,"4",J15<=6,"6",J15<=8,"8",J15<=10,"10",J15<=12,"12",J15<=14,"14",J15<=16,"16",J15<=16,"16",J15<=18,"18",J15<=20,"20") -> 12
A16: 45533 | B16: Boya | C16: 3 | D16: MK-019 | E16: Hat D | F16: UR-1019 | G16: Ölçü Hatası | H16: Renk farkı | I16: 3 | J16: 6.7 | K16: 1 | L16: 327.98 | M16: 17 | N16: Ece | O16: 11 | P16: 815 | Q16: =IF(D16=Pivot!$AS$4,R15, "") | R16: Kontrol tekrarlandı | S16: 1.35 | T16: 94.3 | U16: 92.93 | V16: =K16*I16*J16 -> 20.1 | W16: =U16+L16 -> 420.91 | X16: =_xlfn.IFS(J16<6,"High Quality",J16<=15,"Mid Quality",J16>15,"Low Quality") -> Mid Quality | Y16: =_xlfn.IFS(J16<=0,"0",J16<=2,"2",J16<=4,"4",J16<=6,"6",J16<=8,"8",J16<=10,"10",J16<=12,"12",J16<=14,"14",J16<=16,"16",J16<=16,"16",J16<=18,"18",J16<=20,"20") -> 8
A17: 45368 | B17: Paketleme | C17: 3 | D17: MK-012 | E17: Hat D | F17: UR-1012 | G17: Renk Uyumsuzluğu | H17: Renk farkı | I17: 4 | J17: 3.87 | K17: 9 | L17: 255.35 | M17: 31 | N17: Zeynep | O17: 29 | P17: 352 | Q17: =IF(D17=Pivot!$AS$4,R16, "") | R17: Makine ayarı değiştirildi | S17: 8.24 | T17: 79.52 | U17: 131.93 | V17: =K17*I17*J17 -> 139.32 | W17: =U17+L17 -> 387.28 | X17: =_xlfn.IFS(J17<6,"High Quality",J17<=15,"Mid Quality",J17>15,"Low Quality") -> High Quality | Y17: =_xlfn.IFS(J17<=0,"0",J17<=2,"2",J17<=4,"4",J17<=6,"6",J17<=8,"8",J17<=10,"10",J17<=12,"12",J17<=14,"14",J17<=16,"16",J17<=16,"16",J17<=18,"18",J17<=20,"20") -> 4
A18: 45479 | B18: Pres | C18: 3 | D18: MK-018 | E18: Hat B | F18: UR-1004 | G18: Yüzey Çizik | H18: Tolerans dışı ölçüm | I18: 1 | J18: 6.41 | K18: 2 | L18: 452.34 | M18: 74 | N18: Burak | O18: 34 | P18: 241 | Q18: =IF(D18=Pivot!$AS$4,R17, "") | R18: Eğitim önerildi | S18: 14.11 | T18: 70.78 | U18: 557.89 | V18: =K18*I18*J18 -> 12.82 | W18: =U18+L18 -> 1010.23 | X18: =_xlfn.IFS(J18<6,"High Quality",J18<=15,"Mid Quality",J18>15,"Low Quality") -> Mid Quality | Y18: =_xlfn.IFS(J18<=0,"0",J18<=2,"2",J18<=4,"4",J18<=6,"6",J18<=8,"8",J18<=10,"10",J18<=12,"12",J18<=14,"14",J18<=16,"16",J18<=16,"16",J18<=18,"18",J18<=20,"20") -> 8
A19: 45492 | B19: Pres | C19: 1 | D19: MK-006 | E19: Hat C | F19: UR-1008 | G19: Renk Uyumsuzluğu | H19: Yüzey deformasyonu | I19: 1 | J19: 8.14 | K19: 2 | L19: 274.04 | M19: 63 | N19: Ayşe | O19: 22 | P19: 913 | Q19: =IF(D19=Pivot!$AS$4,R18, "") | R19: Rutin kontrol | S19: 2.41 | T19: 94.18 | U19: 287.74 | V19: =K19*I19*J19 -> 16.28 | W19: =U19+L19 -> 561.78 | X19: =_xlfn.IFS(J19<6,"High Quality",J19<=15,"Mid Quality",J19>15,"Low Quality") -> Mid Quality | Y19: =_xlfn.IFS(J19<=0,"0",J19<=2,"2",J19<=4,"4",J19<=6,"6",J19<=8,"8",J19<=10,"10",J19<=12,"12",J19<=14,"14",J19<=16,"16",J19<=16,"16",J19<=18,"18",J19<=20,"20") -> 10
A20: 45406 | B20: Boya | C20: 3 | D20: MK-018 | E20: Hat C | F20: UR-1005 | G20: Kaynak Hatası | H20: Renk farkı | I20: 3 | J20: 15.37 | K20: 7 | L20: 428.81 | M20: 10 | N20: Ece | O20: 14 | P20: 754 | Q20: =IF(D20=Pivot!$AS$4,R19, "") | R20: Kontrol tekrarlandı | S20: 1.86 | T20: 93.28 | U20: 71.47 | V20: =K20*I20*J20 -> 322.77 | W20: =U20+L20 -> 500.28 | X20: =_xlfn.IFS(J20<6,"High Quality",J20<=15,"Mid Quality",J20>15,"Low Quality") -> Low Quality | Y20: =_xlfn.IFS(J20<=0,"0",J20<=2,"2",J20<=4,"4",J20<=6,"6",J20<=8,"8",J20<=10,"10",J20<=12,"12",J20<=14,"14",J20<=16,"16",J20<=16,"16",J20<=18,"18",J20<=20,"20") -> 16
A21: 45440 | B21: Paketleme | C21: 2 | D21: MK-019 | E21: Hat E | F21: UR-1004 | G21: Kaynak Hatası | H21: Yüzey deformasyonu | I21: 2 | J21: 11.25 | K21: 2 | L21: 410.61 | M21: 27 | N21: Ahmet | O21: 24 | P21: 550 | Q21: =IF(D21=Pivot!$AS$4,R20, "") | R21: Kritik hata | S21: 4.36 | T21: 89.28 | U21: 184.77 | V21: =K21*I21*J21 -> 45 | W21: =U21+L21 -> 595.38 | X21: =_xlfn.IFS(J21<6,"High Quality",J21<=15,"Mid Quality",J21>15,"Low Quality") -> Mid Quality | Y21: =_xlfn.IFS(J21<=0,"0",J21<=2,"2",J21<=4,"4",J21<=6,"6",J21<=8,"8",J21<=10,"10",J21<=12,"12",J21<=14,"14",J21<=16,"16",J21<=16,"16",J21<=18,"18",J21<=20,"20") -> 12
A22: 45360 | B22: CNC | C22: 2 | D22: MK-005 | E22: Hat A | F22: UR-1009 | G22: Eksik Parça | H22: Yüzey deformasyonu | I22: 4 | J22: 2.47 | K22: 8 | L22: 234.73 | M22: 14 | N22: Ahmet | O22: 39 | P22: 882 | Q22: =IF(D22=Pivot!$AS$4,R21, "") | R22: Kritik hata | S22: 4.42 | T22: 87.16 | U22: 54.77 | V22: =K22*I22*J22 -> 79.04 | W22: =U22+L22 -> 289.5 | X22: =_xlfn.IFS(J22<6,"High Quality",J22<=15,"Mid Quality",J22>15,"Low Quality") -> High Quality | Y22: =_xlfn.IFS(J22<=0,"0",J22<=2,"2",J22<=4,"4",J22<=6,"6",J22<=8,"8",J22<=10,"10",J22<=12,"12",J22<=14,"14",J22<=16,"16",J22<=16,"16",J22<=18,"18",J22<=20,"20") -> 4
A23: 45529 | B23: Montaj | C23: 3 | D23: MK-009 | E23: Hat C | F23: UR-1007 | G23: Kaynak Hatası | H23: Eksik vida | I23: 3 | J23: 1.34 | K23: 6 | L23: 153.54 | M23: 55 | N23: Ahmet | O23: 26 | P23: 406 | Q23: =IF(D23=Pivot!$AS$4,R22, "") | R23: Rutin kontrol | S23: 6.4 | T23: 84.2 | U23: 140.74 | V23: =K23*I23*J23 -> 24.12 | W23: =U23+L23 -> 294.28 | X23: =_xlfn.IFS(J23<6,"High Quality",J23<=15,"Mid Quality",J23>15,"Low Quality") -> High Quality | Y23: =_xlfn.IFS(J23<=0,"0",J23<=2,"2",J23<=4,"4",J23<=6,"6",J23<=8,"8",J23<=10,"10",J23<=12,"12",J23<=14,"14",J23<=16,"16",J23<=16,"16",J23<=18,"18",J23<=20,"20") -> 2
A24: 45548 | B24: Paketleme | C24: 3 | D24: MK-003 | E24: Hat A | F24: UR-1006 | G24: Renk Uyumsuzluğu | H24: Tolerans dışı ölçüm | I24: 1 | J24: 2.94 | K24: 7 | L24: 232.74 | M24: 23 | N24: Ahmet | O24: 43 | P24: 599 | Q24: =IF(D24=Pivot!$AS$4,R23, "") | R24: Kritik hata | S24: 7.18 | T24: 84.64 | U24: 89.22 | V24: =K24*I24*J24 -> 20.58 | W24: =U24+L24 -> 321.96 | X24: =_xlfn.IFS(J24<6,"High Quality",J24<=15,"Mid Quality",J24>15,"Low Quality") -> High Quality | Y24: =_xlfn.IFS(J24<=0,"0",J24<=2,"2",J24<=4,"4",J24<=6,"6",J24<=8,"8",J24<=10,"10",J24<=12,"12",J24<=14,"14",J24<=16,"16",J24<=16,"16",J24<=18,"18",J24<=20,"20") -> 4
... A1001: 45479 | B1001: CNC | C1001: 1 | D1001: MK-005 | E1001: Hat B | F1001: UR-1007 | G1001: Ölçü Hatası | H1001: Eksik vida | I1001: 4 | J1001: 8.75 | K1001: 1 | L1001: 376.21 | M1001: 68 | N1001: Ayşe | O1001: 35 | P1001: 519 | Q1001: =IF(D1001=Pivot!$AS$4,R1000, "") | R1001: Makine ayarı değiştirildi | S1001: 6.74 | T1001: 82.52 | U1001: 426.37 | V1001: =K1001*I1001*J1001 -> 35 | W1001: =U1001+L1001 -> 802.58 | X1001: =_xlfn.IFS(J1001<6,"High Quality",J1001<=15,"Mid Quality",J1001>15,"Low Quality") -> Mid Quality | Y1001: =_xlfn.IFS(J1001<=0,"0",J1001<=2,"2",J1001<=4,"4",J1001<=6,"6",J1001<=8,"8",J1001<=10,"10",J1001<=12,"12",J1001<=14,"14",J1001<=16,"16",J1001<=16,"16",J1001<=18,"18",J1001<=20,"20") -> 10

Sheet Pivot
BD2: Score | BE2: =BA4 -> 3
A3: Sum of TotalProduction | B3: Sum of TotalProduction | C3: oran | D3: kalan | F3: Sum of DefectiveUnits | G3: Sum of DefectiveUnits | K3: Satır Etiketleri | L3: Average of ErrorRate (%) | O3: Satır Etiketleri | P3: Sum of DefectiveUnits | R3: Satır Etiketleri | S3: Sum of ErrorFrequency (units/day) | T3: Average of ErrorSeverity (1–5) | U3: Sum of ErrorCost (TL/unit) | V3: Average of ErrorProbability (%) | W3: Average of CorrectionTime (minutes) | X3: Sum of risk score | Z3: Satır Etiketleri | AA3: frequency | AB3: errortype | AC3: frequency | AD3: Satır Etiketleri | AE3: total error cost | AF3: errortype | AG3: toterrorcost | AH3: Satır Etiketleri | AI3: Average of CorrectionTime (minutes) | AJ3: errortype | AK3: avgcorrectiontime | AL3: Satır Etiketleri | AM3: Sum of risk score | AN3: errortype | AO3: riskscore | AP3: Inspector | AQ3: count of inspector in this machine | AS3: machine code | AV3: Inspector Name | AW3: Average of QualityScore (0–100) | AX3: Sum of ErrorFrequency (units/day) | AZ3: Satır Etiketleri | BA3: Average of ErrorSeverity (1–5) | BC3: Value | BD3: Needle | BE3: 0.1 | BL3: ErrorType | BM3: ErrorDescription | BN3: Notes | BO3: Sum of DefectiveUnits | BQ3: ErrorType | BR3: ErrorDescription | BS3: Notes | BT3: Sum of DefectiveUnits | BW3: Sum of Total Cost | BX3: Sum of Total Cost | CB3: error prob | CC3: quality class | CF3: Count of quality classes | CG3: Sütun Etiketleri | CQ3: Count of ErrorDescription | CR3: Sütun Etiketleri | CY3: Satır Etiketleri | CZ3: Sum of normdist | DA3: Sum of uniform | DB3: Sum of countifs | DC3: bins | DD3: normdist | DE3: uniform | DF3: countifs | DH3: Say Notes | DI3: Sütun Etiketleri | DP3: Satır Etiketleri | DQ3: Toplam Total Cost | DR3: months | DS3: total cost
A4: 535557 | B4: 535557 | C4: =A4/B4 -> 1 | D4: =1-C4 -> 0 | F4: 24850 | G4: 24850 | H4: =F4/G4 -> 1 | I4: =1-H4 -> 0 | K4: 01.Oca | L4: 5.086 | O4: 1 | P4: 8387 | R4: Eksik Parça | S4: 1004 | T4: 3 | U4: 52751.76 | V4: 10.086584 | W4: 45.341584 | X4: 31246.93 | Z4: Eksik Parça | AA4: 202 | AB4: =IF(OR(Z4="",Z4="Grand Total",Z4="(blank)"),"",Z4) -> Eksik Parça | AC4: =IFERROR(VLOOKUP(AB4,$Z$3:$AA$9,2,FALSE),"") -> 202 | AD4: Eksik Parça | AE4: 52751.76 | AF4: =IF(OR(AD4="",AD4="Grand Total",AD4="(blank)"),"",AD4) -> Eksik Parça | AG4: =IFERROR(VLOOKUP(AF4,$AD$3:$AE$9,2,FALSE),"") -> 52751.76 | AH4: Eksik Parça | AI4: 45.341584 | AJ4: =IF(OR(AH4="",AH4="Grand Total",AH4="(blank)"),"",AH4) -> Eksik Parça | AK4: =IFERROR(VLOOKUP(AJ4,$AH$3:$AI$9,2,FALSE),"") -> 45.341584 | AL4: Eksik Parça | AM4: 0.20173583 | AN4: =IF(OR(AL4="",AL4="Grand Total",AL4="(blank)"),"",AL4) -> Eksik Parça | AO4: =IFERROR(VLOOKUP(AN4,$AL$3:$AM$9,2,FALSE),"") -> 0.20173583 | AP4: Zeynep | AQ4: 189 | AS4: MK-001 | AV4: Ahmet | AW4: 82.740678 | AX4: 896 | AZ4: Eksik Parça | BA4: 3 | BC4: 1 | BD4: Rest | BE4: =SUM(BC4:BC9)-SUM(BE2:BE3) -> 6.9 | BL4: Eksik Parça | BM4: Eksik vida | BN4: Eğitim önerildi | BO4: 293 | BQ4: Eksik Parça | BR4: Eksik vida | BS4: Eğitim önerildi | BT4: 111 | BW4: 479811.5 | BX4: 479811.5 | BY4: =BW4/BX4 -> 1 | BZ4: =1-BW4/BX4 -> 0 | CB4: <6% | CC4: high quality | CF4: Satır Etiketleri | CG4: High Quality | CH4: Low Quality | CI4: Mid Quality | CJ4: Genel Toplam | CK4: rows | CL4: High Quality | CM4: Mid Quality | CN4: Low Quality | CQ4: Satır Etiketleri | CR4: Renk farkı | CS4: Eksik vida | CT4: Tolerans dışı ölçüm | CU4: Yüzey deformasyonu | CV4: Kaynak atlaması | CW4: Genel Toplam | CY4: 0 | CZ4: 0.012441599 | DA4: 0.05 | DB4: 0 | DC4: =IF(OR(CY4="",CY4="Grand Total",CY4="(blank)"),"",CY4) -> 0 | DD4: =IFERROR(VLOOKUP(DC4,$CY$3:$DA$16,2,FALSE),"") -> 0.012441599 | DE4: =IFERROR(VLOOKUP(DC4,$CY$3:$DA$16,3,FALSE),"") -> 0.05 | DF4: =IFERROR(VLOOKUP(DC4,$CY$3:$DB$16,4,FALSE),"") -> 0 | DH4: Satır Etiketleri | DI4: Eğitim önerildi | DJ4: Kontrol tekrarlandı | DK4: Kritik hata | DL4: Makine ayarı değiştirildi | DM4: Rutin kontrol | DN4: Genel Toplam | DP4: Oca | DQ4: 44707.28 | DR4: =IF(OR(DP4="",DP4="Grand Total",DP4="(blank)"),"",DP4) -> Oca | DS4: =IFERROR(VLOOKUP(DR4,$DP$3:$DQ$14,2,FALSE),"") -> 44707.28
K5: 03.Oca | L5: 6.3233333 | O5: 2 | P5: 8498 | R5: Renk farkı | S5: 246 | T5: 2.9375 | U5: 12816.37 | V5: 10.369375 | W5: 42.833333 | X5: 8419.44 | Z5: Kaynak Hatası | AA5: 207 | AB5: =IF(OR(Z5="",Z5="Grand Total",Z5="(blank)"),"",Z5) -> Kaynak Hatası | AC5: =IFERROR(VLOOKUP(AB5,$Z$3:$AA$9,2,FALSE),"") -> 207 | AD5: Kaynak Hatası | AE5: 58295.89 | AF5: =IF(OR(AD5="",AD5="Grand Total",AD5="(blank)"),"",AD5) -> Kaynak Hatası | AG5: =IFERROR(VLOOKUP(AF5,$AD$3:$AE$9,2,FALSE),"") -> 58295.89 | AH5: Kaynak Hatası | AI5: 44.391304 | AJ5: =IF(OR(AH5="",AH5="Grand Total",AH5="(blank)"),"",AH5) -> Kaynak Hatası | AK5: =IFERROR(VLOOKUP(AJ5,$AH$3:$AI$9,2,FALSE),"") -> 44.391304 | AL5: Kaynak Hatası | AM5: 0.21796222 | AN5: =IF(OR(AL5="",AL5="Grand Total",AL5="(blank)"),"",AL5) -> Kaynak Hatası | AO5: =IFERROR(VLOOKUP(AN5,$AL$3:$AM$9,2,FALSE),"") -> 0.21796222 | AP5: Ahmet | AQ5: 177 | AS5: MK-002 | AV5: Ayşe | AW5: 83.380595 | AX5: 815 | AZ5: Kaynak Hatası | BA5: 3.0772947 | BC5: 1 | BL5: Eksik Parça | BM5: Eksik vida | BN5: Kontrol tekrarlandı | BO5: 210 | BQ5: Eksik Parça | BR5: Eksik vida | BS5: Kontrol tekrarlandı | BT5: 67 | CB5: %6-&%15 | CC5: mid quality | CF5: Boya | CG5: 43 | CH5: 50 | CI5: 71 | CJ5: 164 | CK5: =IF(OR(CF5="",CF5="Grand Total"),"",CF5) -> Boya | CL5: =IFERROR(VLOOKUP(CK5,$CF$3:$CJ$11,2,FALSE),"") -> 43 | CM5: =IFERROR(VLOOKUP(CK5,$CF$3:$CJ$11,3,FALSE),"") -> 50 | CN5: =IFERROR(VLOOKUP(CK5,$CF$3:$CJ$11,4,FALSE),"") -> 71 | CQ5: Eksik Parça | CR5: 48 | CS5: 39 | CT5: 38 | CU5: 38 | CV5: 39 | CW5: 202 | CY5: 2 | CZ5: 0.023031728 | DA5: 0.05 | DB5: 55 | DC5: =IF(OR(CY5="",CY5="Grand Total",CY5="(blank)"),"",CY5) -> 2 | DD5: =IFERROR(VLOOKUP(DC5,$CY$3:$DA$16,2,FALSE),"") -> 0.023031728 | DE5: =IFERROR(VLOOKUP(DC5,$CY$3:$DA$16,3,FALSE),"") -> 0.05 | DF5: =IFERROR(VLOOKUP(DC5,$CY$3:$DB$16,4,FALSE),"") -> 55 | DH5: Eksik Parça | DI5: 42 | DJ5: 41 | DK5: 43 | DL5: 39 | DM5: 37 | DN5: 202 | DP5: Şub | DQ5: 43527.69 | DR5: =IF(OR(DP5="",DP5="Grand Total",DP5="(blank)"),"",DP5) -> Şub | DS5: =IFERROR(VLOOKUP(DR5,$DP$3:$DQ$14,2,FALSE),"") -> 43527.69
K6: 04.Oca | L6: 4.805 | O6: 3 | P6: 7965 | R6: Yüzey deformasyonu | S6: 219 | T6: 3.0263158 | U6: 9768.41 | V6: 9.8205263 | W6: 47.026316 | X6: 7103.14 | Z6: Ölçü Hatası | AA6: 183 | AB6: =IF(OR(Z6="",Z6="Grand Total",Z6="(blank)"),"",Z6) -> Ölçü Hatası | AC6: =IFERROR(VLOOKUP(AB6,$Z$3:$AA$9,2,FALSE),"") -> 183 | AD6: Ölçü Hatası | AE6: 49215.36 | AF6: =IF(OR(AD6="",AD6="Grand Total",AD6="(blank)"),"",AD6) -> Ölçü Hatası | AG6: =IFERROR(VLOOKUP(AF6,$AD$3:$AE$9,2,FALSE),"") -> 49215.36 | AH6: Ölçü Hatası | AI6: 46.617486 | AJ6: =IF(OR(AH6="",AH6="Grand Total",AH6="(blank)"),"",AH6) -> Ölçü Hatası | AK6: =IFERROR(VLOOKUP(AJ6,$AH$3:$AI$9,2,FALSE),"") -> 46.617486 | AL6: Ölçü Hatası | AM6: 0.17616619 | AN6: =IF(OR(AL6="",AL6="Grand Total",AL6="(blank)"),"",AL6) -> Ölçü Hatası | AO6: =IFERROR(VLOOKUP(AN6,$AL$3:$AM$9,2,FALSE),"") -> 0.17616619 | AP6: Ayşe | AQ6: 168 | AS6: MK-003 | AV6: Burak | AW6: 83.436276 | AX6: 627 | AZ6: Ölçü Hatası | BA6: 2.8688525 | BC6: 1 | BL6: Eksik Parça | BM6: Eksik vida | BN6: Kritik hata | BO6: 188 | BQ6: Eksik Parça | BR6: Eksik vida | BS6: Kritik hata | BT6: 93 | CB6: >15% | CC6: low quality | CF6: CNC | CG6: 51 | CH6: 40 | CI6: 81 | CJ6: 172 | CK6: =IF(OR(CF6="",CF6="Grand Total"),"",CF6) -> CNC | CL6: =IFERROR(VLOOKUP(CK6,$CF$3:$CJ$11,2,FALSE),"") -> 51 | CM6: =IFERROR(VLOOKUP(CK6,$CF$3:$CJ$11,3,FALSE),"") -> 40 | CN6: =IFERROR(VLOOKUP(CK6,$CF$3:$CJ$11,4,FALSE),"") -> 81 | CQ6: Kaynak Hatası | CR6: 59 | CS6: 47 | CT6: 33 | CU6: 39 | CV6: 29 | CW6: 207 | CY6: 4 | CZ6: 0.037366808 | DA6: 0.05 | DB6: 112 | DC6: =IF(OR(CY6="",CY6="Grand Total",CY6="(blank)"),"",CY6) -> 4 | DD6: =IFERROR(VLOOKUP(DC6,$CY$3:$DA$16,2,FALSE),"") -> 0.037366808 | DE6: =IFERROR(VLOOKUP(DC6,$CY$3:$DA$16,3,FALSE),"") -> 0.05 | DF6: =IFERROR(VLOOKUP(DC6,$CY$3:$DB$16,4,FALSE),"") -> 112 | DH6: Kaynak Hatası | DI6: 41 | DJ6: 46 | DK6: 44 | DL6: 33 | DM6: 43 | DN6: 207 | DP6: Mar | DQ6: 48319.94 | DR6: =IF(OR(DP6="",DP6="Grand Total",DP6="(blank)"),"",DP6) -> Mar | DS6: =IFERROR(VLOOKUP(DR6,$DP$3:$DQ$14,2,FALSE),"") -> 48319.94
A7: Sum of ErrorCost (TL/unit) | B7: Sum of ErrorCost (TL/unit) | F7: Sum of CorrectionTime (minutes) | G7: Sum of CorrectionTime (minutes) | K7: 05.Oca | L7: 7.2971429 | O7: Genel Toplam | P7: 24850 | R7: Eksik vida | S7: 178 | T7: 3.1025641 | U7: 9118.06 | V7: 10.612821 | W7: 43.897436 | X7: 5483.85 | Z7: Renk Uyumsuzluğu | AA7: 196 | AB7: =IF(OR(Z7="",Z7="Grand Total",Z7="(blank)"),"",Z7) -> Renk Uyumsuzluğu | AC7: =IFERROR(VLOOKUP(AB7,$Z$3:$AA$9,2,FALSE),"") -> 196 | AD7: Renk Uyumsuzluğu | AE7: 53007.4 | AF7: =IF(OR(AD7="",AD7="Grand Total",AD7="(blank)"),"",AD7) -> Renk Uyumsuzluğu | AG7: =IFERROR(VLOOKUP(AF7,$AD$3:$AE$9,2,FALSE),"") -> 53007.4 | AH7: Renk Uyumsuzluğu | AI7: 45.94898 | AJ7: =IF(OR(AH7="",AH7="Grand Total",AH7="(blank)"),"",AH7) -> Renk Uyumsuzluğu | AK7: =IFERROR(VLOOKUP(AJ7,$AH$3:$AI$9,2,FALSE),"") -> 45.94898 | AL7: Renk Uyumsuzluğu | AM7: 0.16954712 | AN7: =IF(OR(AL7="",AL7="Grand Total",AL7="(blank)"),"",AL7) -> Renk Uyumsuzluğu | AO7: =IFERROR(VLOOKUP(AN7,$AL$3:$AM$9,2,FALSE),"") -> 0.16954712 | AP7: Ece | AQ7: 165 | AS7: MK-004 | AV7: Ece | AW7: 84.400242 | AX7: 807 | AZ7: Renk Uyumsuzluğu | BA7: 2.8622449 | BC7: 1 | BL7: Eksik Parça | BM7: Eksik vida | BN7: Makine ayarı değiştirildi | BO7: 179 | BQ7: Eksik Parça | BR7: Eksik vida | BS7: Makine ayarı değiştirildi | BT7: 37 | CF7: Kaynak | CG7: 39 | CH7: 43 | CI7: 72 | CJ7: 154 | CK7: =IF(OR(CF7="",CF7="Grand Total"),"",CF7) -> Kaynak | CL7: =IFERROR(VLOOKUP(CK7,$CF$3:$CJ$11,2,FALSE),"") -> 39 | CM7: =IFERROR(VLOOKUP(CK7,$CF$3:$CJ$11,3,FALSE),"") -> 43 | CN7: =IFERROR(VLOOKUP(CK7,$CF$3:$CJ$11,4,FALSE),"") -> 72 | CQ7: Ölçü Hatası | CR7: 42 | CS7: 44 | CT7: 38 | CU7: 35 | CV7: 24 | CW7: 183 | CY7: 6 | CZ7: 0.053131811 | DA7: 0.05 | DB7: 106 | DC7: =IF(OR(CY7="",CY7="Grand Total",CY7="(blank)"),"",CY7) -> 6 | DD7: =IFERROR(VLOOKUP(DC7,$CY$3:$DA$16,2,FALSE),"") -> 0.053131811 | DE7: =IFERROR(VLOOKUP(DC7,$CY$3:$DA$16,3,FALSE),"") -> 0.05 | DF7: =IFERROR(VLOOKUP(DC7,$CY$3:$DB$16,4,FALSE),"") -> 106 | DH7: Ölçü Hatası | DI7: 25 | DJ7: 39 | DK7: 32 | DL7: 48 | DM7: 39 | DN7: 183 | DP7: Nis | DQ7: 47737.12 | DR7: =IF(OR(DP7="",DP7="Grand Total",DP7="(blank)"),"",DP7) -> Nis | DS7: =IFERROR(VLOOKUP(DR7,$DP$3:$DQ$14,2,FALSE),"") -> 47737.12
A8: 269220.73 | B8: 269220.73 | C8: =A8/B8 -> 1 | D8: =1-C8 -> 0 | F8: 46649 | G8: 46649 | K8: 06.Oca | L8: 6.78 | R8: Kaynak atlaması | S8: 173 | T8: 3.0512821 | U8: 9744.06 | V8: 10.274359 | W8: 40.692308 | X8: 5125.61 | Z8: Yüzey Çizik | AA8: 212 | AB8: =IF(OR(Z8="",Z8="Grand Total",Z8="(blank)"),"",Z8) -> Yüzey Çizik | AC8: =IFERROR(VLOOKUP(AB8,$Z$3:$AA$9,2,FALSE),"") -> 212 | AD8: Yüzey Çizik | AE8: 55950.32 | AF8: =IF(OR(AD8="",AD8="Grand Total",AD8="(blank)"),"",AD8) -> Yüzey Çizik | AG8: =IFERROR(VLOOKUP(AF8,$AD$3:$AE$9,2,FALSE),"") -> 55950.32 | AH8: Yüzey Çizik | AI8: 50.773585 | AJ8: =IF(OR(AH8="",AH8="Grand Total",AH8="(blank)"),"",AH8) -> Yüzey Çizik | AK8: =IFERROR(VLOOKUP(AJ8,$AH$3:$AI$9,2,FALSE),"") -> 50.773585 | AL8: Yüzey Çizik | AM8: 0.23458863 | AN8: =IF(OR(AL8="",AL8="Grand Total",AL8="(blank)"),"",AL8) -> Yüzey Çizik | AO8: =IFERROR(VLOOKUP(AN8,$AL$3:$AM$9,2,FALSE),"") -> 0.23458863 | AP8: Mehmet | AQ8: 156 | AS8: MK-005 | AV8: Mehmet | AW8: 85.296026 | AX8: 848 | AZ8: Yüzey Çizik | BA8: 2.995283 | BC8: 1 | BL8: Eksik Parça | BM8: Eksik vida | BN8: Rutin kontrol | BO8: 110 | CF8: Montaj | CG8: 48 | CH8: 53 | CI8: 80 | CJ8: 181 | CK8: =IF(OR(CF8="",CF8="Grand Total"),"",CF8) -> Montaj | CL8: =IFERROR(VLOOKUP(CK8,$CF$3:$CJ$11,2,FALSE),"") -> 48 | CM8: =IFERROR(VLOOKUP(CK8,$CF$3:$CJ$11,3,FALSE),"") -> 53 | CN8: =IFERROR(VLOOKUP(CK8,$CF$3:$CJ$11,4,FALSE),"") -> 80 | CQ8: Renk Uyumsuzluğu | CR8: 45 | CS8: 36 | CT8: 43 | CU8: 36 | CV8: 36 | CW8: 196 | CY8: 8 | CZ8: 0.066211341 | DA8: 0.05 | DB8: 110 | DC8: =IF(OR(CY8="",CY8="Grand Total",CY8="(blank)"),"",CY8) -> 8 | DD8: =IFERROR(VLOOKUP(DC8,$CY$3:$DA$16,2,FALSE),"") -> 0.066211341 | DE8: =IFERROR(VLOOKUP(DC8,$CY$3:$DA$16,3,FALSE),"") -> 0.05 | DF8: =IFERROR(VLOOKUP(DC8,$CY$3:$DB$16,4,FALSE),"") -> 110 | DH8: Renk Uyumsuzluğu | DI8: 32 | DJ8: 47 | DK8: 36 | DL8: 42 | DM8: 39 | DN8: 196 | DP8: May | DQ8: 52368.8 | DR8: =IF(OR(DP8="",DP8="Grand Total",DP8="(blank)"),"",DP8) -> May | DS8: =IFERROR(VLOOKUP(DR8,$DP$3:$DQ$14,2,FALSE),"") -> 52368.8
K9: 07.Oca | L9: 3.9966667 | R9: Tolerans dışı ölçüm | S9: 188 | T9: 2.8947368 | U9: 11304.86 | V9: 9.2626316 | W9: 53.078947 | X9: 5114.89 | Z9: Genel Toplam | AA9: 1000 | AB9: =IF(OR(Z9="",Z9="Grand Total",Z9="(blank)"),"",Z9) -> Genel Toplam | AC9: =IFERROR(VLOOKUP(AB9,$Z$3:$AA$9,2,FALSE),"") -> 1000 | AD9: Genel Toplam | AE9: 269220.73 | AF9: =IF(OR(AD9="",AD9="Grand Total",AD9="(blank)"),"",AD9) -> Genel Toplam | AG9: =IFERROR(VLOOKUP(AF9,$AD$3:$AE$9,2,FALSE),"") -> 269220.73 | AH9: Genel Toplam | AI9: 46.649 | AJ9: =IF(OR(AH9="",AH9="Grand Total",AH9="(blank)"),"",AH9) -> Genel Toplam | AK9: =IFERROR(VLOOKUP(AJ9,$AH$3:$AI$9,2,FALSE),"") -> 46.649 | AL9: Genel Toplam | AM9: 1 | AN9: =IF(OR(AL9="",AL9="Grand Total",AL9="(blank)"),"",AL9) -> Genel Toplam | AO9: =IFERROR(VLOOKUP(AN9,$AL$3:$AM$9,2,FALSE),"") -> 1 | AP9: Burak | AQ9: 145 | AS9: MK-007 | AV9: Zeynep | AW9: 84.155344 | AX9: 943 | AZ9: Genel Toplam | BA9: 2.964 | BC9: 5 | BL9: Eksik Parça | BM9: Toplam Eksik vida | BO9: 980 | BQ9: Eksik Parça | BR9: Kaynak atlaması | BS9: Eğitim önerildi | BT9: 122 | CF9: Paketleme | CG9: 53 | CH9: 38 | CI9: 83 | CJ9: 174 | CK9: =IF(OR(CF9="",CF9="Grand Total"),"",CF9) -> Paketleme | CL9: =IFERROR(VLOOKUP(CK9,$CF$3:$CJ$11,2,FALSE),"") -> 53 | CM9: =IFERROR(VLOOKUP(CK9,$CF$3:$CJ$11,3,FALSE),"") -> 38 | CN9: =IFERROR(VLOOKUP(CK9,$CF$3:$CJ$11,4,FALSE),"") -> 83 | CQ9: Yüzey Çizik | CR9: 41 | CS9: 42 | CT9: 45 | CU9: 46 | CV9: 38 | CW9: 212 | CY9: 10 | CZ9: 0.072313485 | DA9: 0.05 | DB9: 106 | DC9: =IF(OR(CY9="",CY9="Grand Total",CY9="(blank)"),"",CY9) -> 10 | DD9: =IFERROR(VLOOKUP(DC9,$CY$3:$DA$16,2,FALSE),"") -> 0.072313485 | DE9: =IFERROR(VLOOKUP(DC9,$CY$3:$DA$16,3,FALSE),"") -> 0.05 | DF9: =IFERROR(VLOOKUP(DC9,$CY$3:$DB$16,4,FALSE),"") -> 106 | DH9: Yüzey Çizik | DI9: 43 | DJ9: 45 | DK9: 40 | DL9: 43 | DM9: 41 | DN9: 212 | DP9: Haz | DQ9: 35935.75 | DR9: =IF(OR(DP9="",DP9="Grand Total",DP9="(blank)"),"",DP9) -> Haz | DS9: =IFERROR(VLOOKUP(DR9,$DP$3:$DQ$14,2,FALSE),"") -> 35935.75
K10: 08.Oca | L10: 12.123333 | R10: Kaynak Hatası | S10: 1075 | T10: 3.0772947 | U10: 58295.89 | V10: 10.544734 | W10: 44.391304 | X10: 33760.24 | AB10: =IF(OR(Z10="",Z10="Grand Total",Z10="(blank)"),"",Z10) | AC10: =IFERROR(VLOOKUP(AB10,$Z$3:$AA$9,2,FALSE),"") | AJ10: =IF(OR(AH10="",AH10="Grand Total",AH10="(blank)"),"",AH10) | AK10: =IFERROR(VLOOKUP(AJ10,$AH$3:$AI$9,2,FALSE),"") | AN10: =IF(OR(AL10="",AL10="Grand Total",AL10="(blank)"),"",AL10) | AO10: =IFERROR(VLOOKUP(AN10,$AL$3:$AM$9,2,FALSE),"") | AP10: Genel Toplam | AQ10: 1000 | AS10: MK-008 | AV10: Genel Toplam | AW10: 83.88888 | AX10: 4936 | BL10: Eksik Parça | BM10: Kaynak atlaması | BN10: Eğitim önerildi | BO10: 211 | BQ10: Eksik Parça | BR10: Kaynak atlaması | BS10: Kritik hata | BT10: 2 | CF10: Pres | CG10: 39 | CH10: 42 | CI10: 74 | CJ10: 155 | CK10: =IF(OR(CF10="",CF10="Grand Total"),"",CF10) -> Pres | CL10: =IFERROR(VLOOKUP(CK10,$CF$3:$CJ$11,2,FALSE),"") -> 39 | CM10: =IFERROR(VLOOKUP(CK10,$CF$3:$CJ$11,3,FALSE),"") -> 42 | CN10: =IFERROR(VLOOKUP(CK10,$CF$3:$CJ$11,4,FALSE),"") -> 74 | CQ10: Genel Toplam | CR10: 235 | CS10: 208 | CT10: 197 | CU10: 194 | CV10: 166 | CW10: 1000 | CY10: 12 | CZ10: 0.06921741 | DA10: 0.05 | DB10: 118 | DC10: =IF(OR(CY10="",CY10="Grand Total",CY10="(blank)"),"",CY10) -> 12 | DD10: =IFERROR(VLOOKUP(DC10,$CY$3:$DA$16,2,FALSE),"") -> 0.06921741 | DE10: =IFERROR(VLOOKUP(DC10,$CY$3:$DA$16,3,FALSE),"") -> 0.05 | DF10: =IFERROR(VLOOKUP(DC10,$CY$3:$DB$16,4,FALSE),"") -> 118 | DH10: Genel Toplam | DI10: 183 | DJ10: 218 | DK10: 195 | DL10: 205 | DM10: 199 | DN10: 1000 | DP10: Tem | DQ10: 61218.61 | DR10: =IF(OR(DP10="",DP10="Grand Total",DP10="(blank)"),"",DP10) -> Tem | DS10: =IFERROR(VLOOKUP(DR10,$DP$3:$DQ$14,2,FALSE),"") -> 61218.61
A11: Average of QualityScore (0–100) | F11: Sum of KPI – AverageCorrectionCost (TL) | K11: 09.Oca | L11: 3.005 | R11: Renk farkı | S11: 313 | T11: 2.6779661 | U11: 16321.79 | V11: 10.412542 | W11: 42.711864 | X11: 7910.52 | AS11: MK-009 | BL11: Eksik Parça | BM11: Kaynak atlaması | BN11: Kontrol tekrarlandı | BO11: 161 | BQ11: Eksik Parça | BR11: Kaynak atlaması | BS11: Makine ayarı değiştirildi | BT11: 41 | CF11: Genel Toplam | CG11: 273 | CH11: 266 | CI11: 461 | CJ11: 1000 | CK11: =IF(OR(CF11="",CF11="Grand Total"),"",CF11) -> Genel Toplam | CL11: =IFERROR(VLOOKUP(CK11,$CF$3:$CJ$11,2,FALSE),"") -> 273 | CM11: =IFERROR(VLOOKUP(CK11,$CF$3:$CJ$11,3,FALSE),"") -> 266 | CN11: =IFERROR(VLOOKUP(CK11,$CF$3:$CJ$11,4,FALSE),"") -> 461 | CY11: 14 | CZ11: 0.058065816 | DA11: 0.05 | DB11: 90 | DC11: =IF(OR(CY11="",CY11="Grand Total",CY11="(blank)"),"",CY11) -> 14 | DD11: =IFERROR(VLOOKUP(DC11,$CY$3:$DA$16,2,FALSE),"") -> 0.058065816 | DE11: =IFERROR(VLOOKUP(DC11,$CY$3:$DA$16,3,FALSE),"") -> 0.05 | DF11: =IFERROR(VLOOKUP(DC11,$CY$3:$DB$16,4,FALSE),"") -> 90 | DP11: Ağu | DQ11: 43653.49 | DR11: =IF(OR(DP11="",DP11="Grand Total",DP11="(blank)"),"",DP11) -> Ağu | DS11: =IFERROR(VLOOKUP(DR11,$DP$3:$DQ$14,2,FALSE),"") -> 43653.49
A12: 83.88888 | F12: 210590.77 | K12: 10.Oca | L12: 2.8625 | R12: Eksik vida | S12: 219 | T12: 3.2978723 | U12: 13879.52 | V12: 10.480426 | W12: 45.808511 | X12: 7821.16 | AS12: MK-010 | BL12: Eksik Parça | BM12: Kaynak atlaması | BN12: Kritik hata | BO12: 169 | BQ12: Eksik Parça | BR12: Kaynak atlaması | BS12: Rutin kontrol | BT12: 67 | CY12: 16 | CZ12: 0.042690857 | DA12: 0.05 | DB12: 89 | DC12: =IF(OR(CY12="",CY12="Grand Total",CY12="(blank)"),"",CY12) -> 16 | DD12: =IFERROR(VLOOKUP(DC12,$CY$3:$DA$16,2,FALSE),"") -> 0.042690857 | DE12: =IFERROR(VLOOKUP(DC12,$CY$3:$DA$16,3,FALSE),"") -> 0.05 | DF12: =IFERROR(VLOOKUP(DC12,$CY$3:$DB$16,4,FALSE),"") -> 89 | DP12: Eyl | DQ12: 49548.47 | DR12: =IF(OR(DP12="",DP12="Grand Total",DP12="(blank)"),"",DP12) -> Eyl | DS12: =IFERROR(VLOOKUP(DR12,$DP$3:$DQ$14,2,FALSE),"") -> 49548.47
K13: 11.Oca | L13: 10.25 | R13: Yüzey deformasyonu | S13: 226 | T13: 3.3076923 | U13: 11595.88 | V13: 10.227949 | W13: 43.128205 | X13: 7187.06 | AS13: MK-011 | BL13: Eksik Parça | BM13: Kaynak atlaması | BN13: Makine ayarı değiştirildi | BO13: 128 | CY13: 18 | CZ13: 0.027507958 | DA13: 0.05 | DB13: 105 | DC13: =IF(OR(CY13="",CY13="Grand Total",CY13="(blank)"),"",CY13) -> 18 | DD13: =IFERROR(VLOOKUP(DC13,$CY$3:$DA$16,2,FALSE),"") -> 0.027507958 | DE13: =IFERROR(VLOOKUP(DC13,$CY$3:$DA$16,3,FALSE),"") -> 0.05 | DF13: =IFERROR(VLOOKUP(DC13,$CY$3:$DB$16,4,FALSE),"") -> 105 | DP13: Eki | DQ13: 52794.35 | DR13: =IF(OR(DP13="",DP13="Grand Total",DP13="(blank)"),"",DP13) -> Eki | DS13: =IFERROR(VLOOKUP(DR13,$DP$3:$DQ$14,2,FALSE),"") -> 52794.35
K14: 12.Oca | L14: 3.9225 | R14: Kaynak atlaması | S14: 162 | T14: 2.9655172 | U14: 8458.32 | V14: 12.016552 | W14: 46.344828 | X14: 5904.73 | AS14: MK-012 | BL14: Eksik Parça | BM14: Kaynak atlaması | BN14: Rutin kontrol | BO14: 251 | BQ14: Eksik Parça | BR14: Renk farkı | BS14: Kontrol tekrarlandı | BT14: 71 | CY14: 20 | CZ14: 0.015534274 | DA14: 0.05 | DB14: 109 | DC14: =IF(OR(CY14="",CY14="Grand Total",CY14="(blank)"),"",CY14) -> 20 | DD14: =IFERROR(VLOOKUP(DC14,$CY$3:$DA$16,2,FALSE),"") -> 0.015534274 | DE14: =IFERROR(VLOOKUP(DC14,$CY$3:$DA$16,3,FALSE),"") -> 0.05 | DF14: =IFERROR(VLOOKUP(DC14,$CY$3:$DB$16,4,FALSE),"") -> 109 | DP14: Genel Toplam | DQ14: 479811.5
A15: Sum of KPI – AverageCorrectionCost (TL) | B15: Sum of KPI – AverageCorrectionCost (TL) | F15: Average of ErrorRate (%) | K15: 14.Oca | L15: 5.08 | R15: Tolerans dışı ölçüm | S15: 155 | T15: 3.3030303 | U15: 8040.38 | V15: 9.9536364 | W15: 45.151515 | X15: 4936.77 | AS15: MK-013 | BL15: Eksik Parça | BM15: Toplam Kaynak atlaması | BO15: 920 | BQ15: Eksik Parça | BR15: Renk farkı | BS15: Kritik hata | BT15: 92 | CY15: (boş) | DC15: =IF(OR(CY15="",CY15="Grand Total",CY15="(blank)"),"",CY15) -> (boş) | DD15: =IFERROR(VLOOKUP(DC15,$CY$3:$DA$16,2,FALSE),"") -> 0 | DE15: =IFERROR(VLOOKUP(DC15,$CY$3:$DA$16,3,FALSE),"") -> 0 | DF15: =IFERROR(VLOOKUP(DC15,$CY$3:$DB$16,4,FALSE),"") -> 0
A16: 210590.77 | B16: 210590.77 | F16: 6.57356 | K16: 15.Oca | L16: 4.91 | R16: Ölçü Hatası | S16: 879 | T16: 2.8688525 | U16: 49215.36 | V16: 10.554044 | W16: 46.617486 | X16: 27286.44 | AS16: MK-014 | BL16: Eksik Parça | BM16: Renk farkı | BN16: Eğitim önerildi | BO16: 171 | BQ16: Eksik Parça | BR16: Renk farkı | BS16: Makine ayarı değiştirildi | BT16: 195 | CY16: Genel Toplam | CZ16: 0.47751309 | DA16: 0.55 | DB16: 1000 | DC16: =IF(OR(CY16="",CY16="Grand Total",CY16="(blank)"),"",CY16) -> Genel Toplam | DD16: =IFERROR(VLOOKUP(DC16,$CY$3:$DA$16,2,FALSE),"") -> 0.47751309 | DE16: =IFERROR(VLOOKUP(DC16,$CY$3:$DA$16,3,FALSE),"") -> 0.55 | DF16: =IFERROR(VLOOKUP(DC16,$CY$3:$DB$16,4,FALSE),"") -> 1000
K17: 16.Oca | L17: 5.02 | R17: Tolerans dışı ölçüm | S17: 191 | T17: 3 | U17: 9793.55 | V17: 11.577368 | W17: 50.289474 | X17: 6950 | AS17: MK-015 | BL17: Eksik Parça | BM17: Renk farkı | BN17: Kontrol tekrarlandı | BO17: 301 | BQ17: Eksik Parça | BR17: Renk farkı | BS17: Rutin kontrol | BT17: 7
K18: 17.Oca | L18: 10.005 | R18: Eksik vida | S18: 191 | T18: 3.0227273 | U18: 11081.35 | V18: 9.4697727 | W18: 40.522727 | X18: 6193.08 | AS18: MK-016 | BL18: Eksik Parça | BM18: Renk farkı | BN18: Kritik hata | BO18: 319
A19: ErrorCost | B19: CorrectionCost | K19: 18.Oca | L19: 9.3675 | R19: Renk farkı | S19: 201 | T19: 2.8095238 | U19: 11447.39 | V19: 10.816905 | W19: 45.52381 | X19: 5948.42 | AS19: MK-017 | BL19: Eksik Parça | BM19: Renk farkı | BN19: Makine ayarı değiştirildi | BO19: 300 | BQ19: Eksik Parça | BR19: Tolerans dışı ölçüm | BS19: Eğitim önerildi | BT19: 41
A20: =A8 -> 269220.73 | B20: =A16 -> 210590.77 | K20: 19.Oca | L20: 7.07 | R20: Yüzey deformasyonu | S20: 165 | T20: 2.8 | U20: 10454.88 | V20: 10.989429 | W20: 48.542857 | X20: 4620.53 | AS20: MK-018 | BL20: Eksik Parça | BM20: Renk farkı | BN20: Rutin kontrol | BO20: 206 | BQ20: Eksik Parça | BR20: Tolerans dışı ölçüm | BS20: Kontrol tekrarlandı | BT20: 44
K21: 20.Oca | L21: 5.115 | R21: Kaynak atlaması | S21: 131 | T21: 2.5833333 | U21: 6438.19 | V21: 9.8266667 | W21: 51.083333 | X21: 3574.41 | AS21: MK-019 | BL21: Eksik Parça | BM21: Toplam Renk farkı | BO21: 1297 | BQ21: Eksik Parça | BR21: Tolerans dışı ölçüm | BS21: Kritik hata | BT21: 16
K22: 21.Oca | L22: 5.044 | R22: Renk Uyumsuzluğu | S22: 918 | T22: 2.8622449 | U22: 53007.4 | V22: 9.8591837 | W22: 45.94898 | X22: 26261.21 | AS22: MK-020 | BL22: Eksik Parça | BM22: Tolerans dışı ölçüm | BN22: Eğitim önerildi | BO22: 269 | BQ22: Eksik Parça | BR22: Tolerans dışı ölçüm | BS22: Rutin kontrol | BT22: 14
K23: 22.Oca | L23: 8.43 | R23: Tolerans dışı ölçüm | S23: 194 | T23: 3 | U23: 11799.07 | V23: 12.269302 | W23: 56.953488 | X23: 7562.11 | AS23: MK-006 | BL23: Eksik Parça | BM23: Tolerans dışı ölçüm | BN23: Kontrol tekrarlandı | BO23: 120
K24: 23.Oca | L24: 6.7766667 | R24: Renk farkı | S24: 224 | T24: 2.7111111 | U24: 13301.23 | V24: 8.2828889 | W24: 43.066667 | X24: 5292.81 | BL24: Eksik Parça | BM24: Tolerans dışı ölçüm | BN24: Kritik hata | BO24: 218 | BQ24: Eksik Parça | BR24: Yüzey deformasyonu | BS24: Eğitim önerildi | BT24: 30
K25: 24.Oca | L25: 9.02 | R25: Eksik vida | S25: 168 | T25: 2.9444444 | U25: 10228.86 | V25: 9.9013889 | W25: 44.277778 | X25: 4943.88 | BL25: Eksik Parça | BM25: Tolerans dışı ölçüm | BN25: Makine ayarı değiştirildi | BO25: 151 | BQ25: Eksik Parça | BR25: Yüzey deformasyonu | BS25: Kontrol tekrarlandı | BT25: 19
K26: 25.Oca | L26: 0.8 | R26: Kaynak atlaması | S26: 168 | T26: 3.1388889 | U26: 8306.45 | V26: 9.8922222 | W26: 36.861111 | X26: 4668.42 | BL26: Eksik Parça | BM26: Tolerans dışı ölçüm | BN26: Rutin kontrol | BO26: 104 | BQ26: Eksik Parça | BR26: Yüzey deformasyonu | BS26: Kritik hata | BT26: 44
K27: 26.Oca | L27: 4.535 | R27: Yüzey deformasyonu | S27: 164 | T27: 2.5277778 | U27: 9371.79 | V27: 8.8755556 | W27: 47.166667 | X27: 3793.99 | BL27: Eksik Parça | BM27: Toplam Tolerans dışı ölçüm | BO27: 862 | BQ27: Eksik Parça | BR27: Yüzey deformasyonu | BS27: Makine ayarı değiştirildi | BT27: 42
K28: 27.Oca | L28: 10.975 | R28: Yüzey Çizik | S28: 1060 | T28: 2.995283 | U28: 55950.32 | V28: 10.625189 | W28: 50.773585 | X28: 36335.51 | BL28: Eksik Parça | BM28: Yüzey deformasyonu | BN28: Eğitim önerildi | BO28: 175 | BQ28: Eksik Parça | BR28: Yüzey deformasyonu | BS28: Rutin kontrol | BT28: 41
K29: 28.Oca | L29: 8.6366667 | R29: Tolerans dışı ölçüm | S29: 229 | T29: 3.2444444 | U29: 13498.62 | V29: 10.150444 | W29: 52.377778 | X29: 8359.3 | BL29: Eksik Parça | BM29: Yüzey deformasyonu | BN29: Kontrol tekrarlandı | BO29: 165
K30: 29.Oca | L30: 3.55 | R30: Yüzey deformasyonu | S30: 253 | T30: 2.826087 | U30: 11015.95 | V30: 10.444565 | W30: 46.73913 | X30: 8336.7 | BL30: Eksik Parça | BM30: Yüzey deformasyonu | BN30: Kritik hata | BO30: 263
K31: 30.Oca | L31: 10.06 | R31: Renk farkı | S31: 207 | T31: 3.0243902 | U31: 10196.69 | V31: 10.392683 | W31: 55.170732 | X31: 7156.97 | BL31: Eksik Parça | BM31: Yüzey deformasyonu | BN31: Makine ayarı değiştirildi | BO31: 168 | BQ31: Kaynak Hatası | BR31: Eksik vida | BS31: Kontrol tekrarlandı | BT31: 50
K32: 31.Oca | L32: 4.37 | R32: Eksik vida | S32: 187 | T32: 2.9761905 | U32: 10527.55 | V32: 12.079286 | W32: 52.5 | X32: 6969.39 | BL32: Eksik Parça | BM32: Yüzey deformasyonu | BN32: Rutin kontrol | BO32: 135 | BQ32: Kaynak Hatası | BR32: Eksik vida | BS32: Kritik hata | BT32: 102
K33: 01.Şub | L33: 1.14 | R33: Kaynak atlaması | S33: 184 | T33: 2.8947368 | U33: 10711.51 | V33: 10.049737 | W33: 47.105263 | X33: 5513.15 | BL33: Eksik Parça | BM33: Toplam Yüzey deformasyonu | BO33: 906 | BQ33: Kaynak Hatası | BR33: Eksik vida | BS33: Makine ayarı değiştirildi | BT33: 50
K34: 02.Şub | L34: 4.68 | R34: Genel Toplam | S34: 4936 | T34: 2.964 | U34: 269220.73 | V34: 10.33658 | W34: 46.649 | X34: 154890.33 | BL34: Toplam Eksik Parça | BO34: 4965 | BQ34: Kaynak Hatası | BR34: Eksik vida | BS34: Rutin kontrol | BT34: 160
K35: 04.Şub | L35: 13.86 | BL35: Kaynak Hatası | BM35: Eksik vida | BN35: Eğitim önerildi | BO35: 187
K36: 05.Şub | L36: 3.86 | BL36: Kaynak Hatası | BM36: Eksik vida | BN36: Kontrol tekrarlandı | BO36: 371 | BQ36: Kaynak Hatası | BR36: Kaynak atlaması | BS36: Kontrol tekrarlandı | BT36: 19
K37: 06.Şub | L37: 15.284 | BL37: Kaynak Hatası | BM37: Eksik vida | BN37: Kritik hata | BO37: 220 | BQ37: Kaynak Hatası | BR37: Kaynak atlaması | BS37: Makine ayarı değiştirildi | BT37: 39
K38: 07.Şub | L38: 1.53 | BL38: Kaynak Hatası | BM38: Eksik vida | BN38: Makine ayarı değiştirildi | BO38: 195
K39: 08.Şub | L39: 5.485 | BL39: Kaynak Hatası | BM39: Eksik vida | BN39: Rutin kontrol | BO39: 358 | BQ39: Kaynak Hatası | BR39: Renk farkı | BS39: Eğitim önerildi | BT39: 29
K40: 09.Şub | L40: 7.432 | BL40: Kaynak Hatası | BM40: Toplam Eksik vida | BO40: 1331 | BQ40: Kaynak Hatası | BR40: Renk farkı | BS40: Kontrol tekrarlandı | BT40: 33
K41: 10.Şub | L41: 6.30625 | BL41: Kaynak Hatası | BM41: Kaynak atlaması | BN41: Eğitim önerildi | BO41: 134 | BQ41: Kaynak Hatası | BR41: Renk farkı | BS41: Kritik hata | BT41: 29
...
